2015-05-10 14:39:14.078 [IPEngineApp] Loading url_file u'/Users/robert/.ipython/profile_basic/security/ipcontroller-engine.json'
2015-05-10 14:39:14.080 [IPEngineApp] Registering with controller at tcp://127.0.0.1:49580
2015-05-10 14:39:14.191 [IPEngineApp] Starting to monitor the heartbeat signal from the hub every 3010 ms.
2015-05-10 14:39:14.195 [IPEngineApp] Using existing profile dir: u'/Users/robert/.ipython/profile_basic'
2015-05-10 14:39:14.196 [IPEngineApp] Completed registration with id 1
2015-05-11 00:06:00.588 [IPEngineApp] Exception in apply request:
[0;31m---------------------------------------------------------------------------[0m
[0;31mIOError[0m                                   Traceback (most recent call last)
[0;32m<string>[0m in [0;36m<module>[0;34m()[0m

[0;32m<ipython-input-252-919d26c4c7e6>[0m in [0;36mfile_process[0;34m(f)[0m

[0;32m<ipython-input-252-919d26c4c7e6>[0m in [0;36mget_meta_data[0;34m(filename)[0m

[0;32m<ipython-input-252-919d26c4c7e6>[0m in [0;36mget_data_file[0;34m(filename, report)[0m

[0;31mIOError[0m: [Errno 2] No such file or directory: 'c:/DropBox/Investigations/Signal_Quality_Assessment/data/ASH_2015_01_02_15_46.csv'
2015-05-11 00:07:33.777 [IPEngineApp] Exception in apply request:
[0;31m---------------------------------------------------------------------------[0m
[0;31mIOError[0m                                   Traceback (most recent call last)
[0;32m<string>[0m in [0;36m<module>[0;34m()[0m

[0;32m<ipython-input-254-51e20ff31b9b>[0m in [0;36mfile_process[0;34m(f)[0m

[0;32m<ipython-input-254-51e20ff31b9b>[0m in [0;36mget_meta_data[0;34m(filename)[0m

[0;32m<ipython-input-254-51e20ff31b9b>[0m in [0;36mget_data_file[0;34m(filename, report)[0m

[0;31mIOError[0m: [Errno 2] No such file or directory: '/User/Robert/DropBox/Investigations/Signal_Quality_Assessment/data/ASH_2015_01_02_15_46.csv'
2015-05-11 00:09:02.006 [IPEngineApp] Exception in apply request:
[0;31m---------------------------------------------------------------------------[0m
[0;31mNameError[0m                                 Traceback (most recent call last)
[0;32m<string>[0m in [0;36m<module>[0;34m()[0m

[0;32m<ipython-input-256-802b06f4b817>[0m in [0;36mfile_process[0;34m(f)[0m

[0;32m<ipython-input-256-802b06f4b817>[0m in [0;36mMergeTimebasedset[0;34m(Events, SetToMerge)[0m

[0;31mNameError[0m: global name 'DateOffset' is not defined
2015-05-11 00:30:28.049 [IPEngineApp] Exception in apply request:
[0;31m---------------------------------------------------------------------------[0m
[0;31mNameError[0m                                 Traceback (most recent call last)
[0;32m<string>[0m in [0;36m<module>[0;34m()[0m

[0;32m<ipython-input-271-baf08f7be7b5>[0m in [0;36mfile_process[0;34m(f)[0m

[0;31mNameError[0m: global name 'eventDescriptions' is not defined
